{
 "cells": [
  {
   "cell_type": "code",
   "execution_count": 28,
   "metadata": {},
   "outputs": [
    {
     "name": "stdout",
     "output_type": "stream",
     "text": [
      "Collecting pandas\n",
      "  Downloading pandas-1.4.2-cp310-cp310-win_amd64.whl (10.6 MB)\n",
      "Requirement already satisfied: python-dateutil>=2.8.1 in c:\\users\\user\\appdata\\local\\programs\\python\\python310\\lib\\site-packages (from pandas) (2.8.2)\n",
      "Collecting pytz>=2020.1\n",
      "  Downloading pytz-2022.1-py2.py3-none-any.whl (503 kB)\n",
      "Collecting numpy>=1.21.0\n",
      "  Downloading numpy-1.22.3-cp310-cp310-win_amd64.whl (14.7 MB)\n"
     ]
    },
    {
     "name": "stderr",
     "output_type": "stream",
     "text": [
      "ERROR: Exception:\n",
      "Traceback (most recent call last):\n",
      "  File \"C:\\Users\\User\\AppData\\Local\\Programs\\Python\\Python310\\lib\\site-packages\\pip\\_vendor\\urllib3\\response.py\", line 438, in _error_catcher\n",
      "    yield\n",
      "  File \"C:\\Users\\User\\AppData\\Local\\Programs\\Python\\Python310\\lib\\site-packages\\pip\\_vendor\\urllib3\\response.py\", line 519, in read\n",
      "    data = self._fp.read(amt) if not fp_closed else b\"\"\n",
      "  File \"C:\\Users\\User\\AppData\\Local\\Programs\\Python\\Python310\\lib\\site-packages\\pip\\_vendor\\cachecontrol\\filewrapper.py\", line 62, in read\n",
      "    data = self.__fp.read(amt)\n",
      "  File \"C:\\Users\\User\\AppData\\Local\\Programs\\Python\\Python310\\lib\\http\\client.py\", line 465, in read\n",
      "    s = self.fp.read(amt)\n",
      "  File \"C:\\Users\\User\\AppData\\Local\\Programs\\Python\\Python310\\lib\\socket.py\", line 705, in readinto\n",
      "    return self._sock.recv_into(b)\n",
      "  File \"C:\\Users\\User\\AppData\\Local\\Programs\\Python\\Python310\\lib\\ssl.py\", line 1273, in recv_into\n",
      "    return self.read(nbytes, buffer)\n",
      "  File \"C:\\Users\\User\\AppData\\Local\\Programs\\Python\\Python310\\lib\\ssl.py\", line 1129, in read\n",
      "    return self._sslobj.read(len, buffer)\n",
      "TimeoutError: The read operation timed out\n",
      "\n",
      "During handling of the above exception, another exception occurred:\n",
      "\n",
      "Traceback (most recent call last):\n",
      "  File \"C:\\Users\\User\\AppData\\Local\\Programs\\Python\\Python310\\lib\\site-packages\\pip\\_internal\\cli\\base_command.py\", line 173, in _main\n",
      "    status = self.run(options, args)\n",
      "  File \"C:\\Users\\User\\AppData\\Local\\Programs\\Python\\Python310\\lib\\site-packages\\pip\\_internal\\cli\\req_command.py\", line 203, in wrapper\n",
      "    return func(self, options, args)\n",
      "  File \"C:\\Users\\User\\AppData\\Local\\Programs\\Python\\Python310\\lib\\site-packages\\pip\\_internal\\commands\\install.py\", line 315, in run\n",
      "    requirement_set = resolver.resolve(\n",
      "  File \"C:\\Users\\User\\AppData\\Local\\Programs\\Python\\Python310\\lib\\site-packages\\pip\\_internal\\resolution\\resolvelib\\resolver.py\", line 94, in resolve\n",
      "    result = self._result = resolver.resolve(\n",
      "  File \"C:\\Users\\User\\AppData\\Local\\Programs\\Python\\Python310\\lib\\site-packages\\pip\\_vendor\\resolvelib\\resolvers.py\", line 472, in resolve\n",
      "    state = resolution.resolve(requirements, max_rounds=max_rounds)\n",
      "  File \"C:\\Users\\User\\AppData\\Local\\Programs\\Python\\Python310\\lib\\site-packages\\pip\\_vendor\\resolvelib\\resolvers.py\", line 366, in resolve\n",
      "    failure_causes = self._attempt_to_pin_criterion(name)\n",
      "  File \"C:\\Users\\User\\AppData\\Local\\Programs\\Python\\Python310\\lib\\site-packages\\pip\\_vendor\\resolvelib\\resolvers.py\", line 212, in _attempt_to_pin_criterion\n",
      "    criteria = self._get_updated_criteria(candidate)\n",
      "  File \"C:\\Users\\User\\AppData\\Local\\Programs\\Python\\Python310\\lib\\site-packages\\pip\\_vendor\\resolvelib\\resolvers.py\", line 203, in _get_updated_criteria\n",
      "    self._add_to_criteria(criteria, requirement, parent=candidate)\n",
      "  File \"C:\\Users\\User\\AppData\\Local\\Programs\\Python\\Python310\\lib\\site-packages\\pip\\_vendor\\resolvelib\\resolvers.py\", line 172, in _add_to_criteria\n",
      "    if not criterion.candidates:\n",
      "  File \"C:\\Users\\User\\AppData\\Local\\Programs\\Python\\Python310\\lib\\site-packages\\pip\\_vendor\\resolvelib\\structs.py\", line 151, in __bool__\n",
      "    return bool(self._sequence)\n",
      "  File \"C:\\Users\\User\\AppData\\Local\\Programs\\Python\\Python310\\lib\\site-packages\\pip\\_internal\\resolution\\resolvelib\\found_candidates.py\", line 140, in __bool__\n",
      "    return any(self)\n",
      "  File \"C:\\Users\\User\\AppData\\Local\\Programs\\Python\\Python310\\lib\\site-packages\\pip\\_internal\\resolution\\resolvelib\\found_candidates.py\", line 128, in <genexpr>\n",
      "    return (c for c in iterator if id(c) not in self._incompatible_ids)\n",
      "  File \"C:\\Users\\User\\AppData\\Local\\Programs\\Python\\Python310\\lib\\site-packages\\pip\\_internal\\resolution\\resolvelib\\found_candidates.py\", line 32, in _iter_built\n",
      "    candidate = func()\n",
      "  File \"C:\\Users\\User\\AppData\\Local\\Programs\\Python\\Python310\\lib\\site-packages\\pip\\_internal\\resolution\\resolvelib\\factory.py\", line 204, in _make_candidate_from_link\n",
      "    self._link_candidate_cache[link] = LinkCandidate(\n",
      "  File \"C:\\Users\\User\\AppData\\Local\\Programs\\Python\\Python310\\lib\\site-packages\\pip\\_internal\\resolution\\resolvelib\\candidates.py\", line 295, in __init__\n",
      "    super().__init__(\n",
      "  File \"C:\\Users\\User\\AppData\\Local\\Programs\\Python\\Python310\\lib\\site-packages\\pip\\_internal\\resolution\\resolvelib\\candidates.py\", line 156, in __init__\n",
      "    self.dist = self._prepare()\n",
      "  File \"C:\\Users\\User\\AppData\\Local\\Programs\\Python\\Python310\\lib\\site-packages\\pip\\_internal\\resolution\\resolvelib\\candidates.py\", line 227, in _prepare\n",
      "    dist = self._prepare_distribution()\n",
      "  File \"C:\\Users\\User\\AppData\\Local\\Programs\\Python\\Python310\\lib\\site-packages\\pip\\_internal\\resolution\\resolvelib\\candidates.py\", line 305, in _prepare_distribution\n",
      "    return self._factory.preparer.prepare_linked_requirement(\n",
      "  File \"C:\\Users\\User\\AppData\\Local\\Programs\\Python\\Python310\\lib\\site-packages\\pip\\_internal\\operations\\prepare.py\", line 508, in prepare_linked_requirement\n",
      "    return self._prepare_linked_requirement(req, parallel_builds)\n",
      "  File \"C:\\Users\\User\\AppData\\Local\\Programs\\Python\\Python310\\lib\\site-packages\\pip\\_internal\\operations\\prepare.py\", line 550, in _prepare_linked_requirement\n",
      "    local_file = unpack_url(\n",
      "  File \"C:\\Users\\User\\AppData\\Local\\Programs\\Python\\Python310\\lib\\site-packages\\pip\\_internal\\operations\\prepare.py\", line 239, in unpack_url\n",
      "    file = get_http_url(\n",
      "  File \"C:\\Users\\User\\AppData\\Local\\Programs\\Python\\Python310\\lib\\site-packages\\pip\\_internal\\operations\\prepare.py\", line 102, in get_http_url\n",
      "    from_path, content_type = download(link, temp_dir.path)\n",
      "  File \"C:\\Users\\User\\AppData\\Local\\Programs\\Python\\Python310\\lib\\site-packages\\pip\\_internal\\network\\download.py\", line 145, in __call__\n",
      "    for chunk in chunks:\n",
      "  File \"C:\\Users\\User\\AppData\\Local\\Programs\\Python\\Python310\\lib\\site-packages\\pip\\_internal\\cli\\progress_bars.py\", line 144, in iter\n",
      "    for x in it:\n",
      "  File \"C:\\Users\\User\\AppData\\Local\\Programs\\Python\\Python310\\lib\\site-packages\\pip\\_internal\\network\\utils.py\", line 63, in response_chunks\n",
      "    for chunk in response.raw.stream(\n",
      "  File \"C:\\Users\\User\\AppData\\Local\\Programs\\Python\\Python310\\lib\\site-packages\\pip\\_vendor\\urllib3\\response.py\", line 576, in stream\n",
      "    data = self.read(amt=amt, decode_content=decode_content)\n",
      "  File \"C:\\Users\\User\\AppData\\Local\\Programs\\Python\\Python310\\lib\\site-packages\\pip\\_vendor\\urllib3\\response.py\", line 512, in read\n",
      "    with self._error_catcher():\n",
      "  File \"C:\\Users\\User\\AppData\\Local\\Programs\\Python\\Python310\\lib\\contextlib.py\", line 153, in __exit__\n",
      "    self.gen.throw(typ, value, traceback)\n",
      "  File \"C:\\Users\\User\\AppData\\Local\\Programs\\Python\\Python310\\lib\\site-packages\\pip\\_vendor\\urllib3\\response.py\", line 443, in _error_catcher\n",
      "    raise ReadTimeoutError(self._pool, None, \"Read timed out.\")\n",
      "pip._vendor.urllib3.exceptions.ReadTimeoutError: HTTPSConnectionPool(host='files.pythonhosted.org', port=443): Read timed out.\n",
      "WARNING: You are using pip version 21.2.4; however, version 22.0.4 is available.\n",
      "You should consider upgrading via the 'C:\\Users\\User\\AppData\\Local\\Programs\\Python\\Python310\\python.exe -m pip install --upgrade pip' command.\n"
     ]
    },
    {
     "name": "stdout",
     "output_type": "stream",
     "text": [
      "^C\n",
      "Note: you may need to restart the kernel to use updated packages.\n"
     ]
    },
    {
     "name": "stderr",
     "output_type": "stream",
     "text": [
      "ERROR: Exception:\n",
      "Traceback (most recent call last):\n",
      "  File \"C:\\Users\\User\\AppData\\Local\\Programs\\Python\\Python310\\lib\\site-packages\\pip\\_vendor\\urllib3\\response.py\", line 438, in _error_catcher\n",
      "    yield\n",
      "  File \"C:\\Users\\User\\AppData\\Local\\Programs\\Python\\Python310\\lib\\site-packages\\pip\\_vendor\\urllib3\\response.py\", line 519, in read\n",
      "    data = self._fp.read(amt) if not fp_closed else b\"\"\n",
      "  File \"C:\\Users\\User\\AppData\\Local\\Programs\\Python\\Python310\\lib\\site-packages\\pip\\_vendor\\cachecontrol\\filewrapper.py\", line 62, in read\n",
      "    data = self.__fp.read(amt)\n",
      "  File \"C:\\Users\\User\\AppData\\Local\\Programs\\Python\\Python310\\lib\\http\\client.py\", line 465, in read\n",
      "    s = self.fp.read(amt)\n",
      "  File \"C:\\Users\\User\\AppData\\Local\\Programs\\Python\\Python310\\lib\\socket.py\", line 705, in readinto\n",
      "    return self._sock.recv_into(b)\n",
      "  File \"C:\\Users\\User\\AppData\\Local\\Programs\\Python\\Python310\\lib\\ssl.py\", line 1273, in recv_into\n",
      "    return self.read(nbytes, buffer)\n",
      "  File \"C:\\Users\\User\\AppData\\Local\\Programs\\Python\\Python310\\lib\\ssl.py\", line 1129, in read\n",
      "    return self._sslobj.read(len, buffer)\n",
      "TimeoutError: The read operation timed out\n",
      "\n",
      "During handling of the above exception, another exception occurred:\n",
      "\n",
      "Traceback (most recent call last):\n",
      "  File \"C:\\Users\\User\\AppData\\Local\\Programs\\Python\\Python310\\lib\\site-packages\\pip\\_internal\\cli\\base_command.py\", line 173, in _main\n",
      "    status = self.run(options, args)\n",
      "  File \"C:\\Users\\User\\AppData\\Local\\Programs\\Python\\Python310\\lib\\site-packages\\pip\\_internal\\cli\\req_command.py\", line 203, in wrapper\n",
      "    return func(self, options, args)\n",
      "  File \"C:\\Users\\User\\AppData\\Local\\Programs\\Python\\Python310\\lib\\site-packages\\pip\\_internal\\commands\\install.py\", line 315, in run\n",
      "    requirement_set = resolver.resolve(\n",
      "  File \"C:\\Users\\User\\AppData\\Local\\Programs\\Python\\Python310\\lib\\site-packages\\pip\\_internal\\resolution\\resolvelib\\resolver.py\", line 94, in resolve\n",
      "    result = self._result = resolver.resolve(\n",
      "  File \"C:\\Users\\User\\AppData\\Local\\Programs\\Python\\Python310\\lib\\site-packages\\pip\\_vendor\\resolvelib\\resolvers.py\", line 472, in resolve\n",
      "    state = resolution.resolve(requirements, max_rounds=max_rounds)\n",
      "  File \"C:\\Users\\User\\AppData\\Local\\Programs\\Python\\Python310\\lib\\site-packages\\pip\\_vendor\\resolvelib\\resolvers.py\", line 366, in resolve\n",
      "    failure_causes = self._attempt_to_pin_criterion(name)\n",
      "  File \"C:\\Users\\User\\AppData\\Local\\Programs\\Python\\Python310\\lib\\site-packages\\pip\\_vendor\\resolvelib\\resolvers.py\", line 212, in _attempt_to_pin_criterion\n",
      "    criteria = self._get_updated_criteria(candidate)\n",
      "  File \"C:\\Users\\User\\AppData\\Local\\Programs\\Python\\Python310\\lib\\site-packages\\pip\\_vendor\\resolvelib\\resolvers.py\", line 203, in _get_updated_criteria\n",
      "    self._add_to_criteria(criteria, requirement, parent=candidate)\n",
      "  File \"C:\\Users\\User\\AppData\\Local\\Programs\\Python\\Python310\\lib\\site-packages\\pip\\_vendor\\resolvelib\\resolvers.py\", line 172, in _add_to_criteria\n",
      "    if not criterion.candidates:\n",
      "  File \"C:\\Users\\User\\AppData\\Local\\Programs\\Python\\Python310\\lib\\site-packages\\pip\\_vendor\\resolvelib\\structs.py\", line 151, in __bool__\n",
      "    return bool(self._sequence)\n",
      "  File \"C:\\Users\\User\\AppData\\Local\\Programs\\Python\\Python310\\lib\\site-packages\\pip\\_internal\\resolution\\resolvelib\\found_candidates.py\", line 140, in __bool__\n",
      "    return any(self)\n",
      "  File \"C:\\Users\\User\\AppData\\Local\\Programs\\Python\\Python310\\lib\\site-packages\\pip\\_internal\\resolution\\resolvelib\\found_candidates.py\", line 128, in <genexpr>\n",
      "    return (c for c in iterator if id(c) not in self._incompatible_ids)\n",
      "  File \"C:\\Users\\User\\AppData\\Local\\Programs\\Python\\Python310\\lib\\site-packages\\pip\\_internal\\resolution\\resolvelib\\found_candidates.py\", line 32, in _iter_built\n",
      "    candidate = func()\n",
      "  File \"C:\\Users\\User\\AppData\\Local\\Programs\\Python\\Python310\\lib\\site-packages\\pip\\_internal\\resolution\\resolvelib\\factory.py\", line 204, in _make_candidate_from_link\n",
      "    self._link_candidate_cache[link] = LinkCandidate(\n",
      "  File \"C:\\Users\\User\\AppData\\Local\\Programs\\Python\\Python310\\lib\\site-packages\\pip\\_internal\\resolution\\resolvelib\\candidates.py\", line 295, in __init__\n",
      "    super().__init__(\n",
      "  File \"C:\\Users\\User\\AppData\\Local\\Programs\\Python\\Python310\\lib\\site-packages\\pip\\_internal\\resolution\\resolvelib\\candidates.py\", line 156, in __init__\n",
      "    self.dist = self._prepare()\n",
      "  File \"C:\\Users\\User\\AppData\\Local\\Programs\\Python\\Python310\\lib\\site-packages\\pip\\_internal\\resolution\\resolvelib\\candidates.py\", line 227, in _prepare\n",
      "    dist = self._prepare_distribution()\n",
      "  File \"C:\\Users\\User\\AppData\\Local\\Programs\\Python\\Python310\\lib\\site-packages\\pip\\_internal\\resolution\\resolvelib\\candidates.py\", line 305, in _prepare_distribution\n",
      "    return self._factory.preparer.prepare_linked_requirement(\n",
      "  File \"C:\\Users\\User\\AppData\\Local\\Programs\\Python\\Python310\\lib\\site-packages\\pip\\_internal\\operations\\prepare.py\", line 508, in prepare_linked_requirement\n",
      "    return self._prepare_linked_requirement(req, parallel_builds)\n",
      "  File \"C:\\Users\\User\\AppData\\Local\\Programs\\Python\\Python310\\lib\\site-packages\\pip\\_internal\\operations\\prepare.py\", line 550, in _prepare_linked_requirement\n",
      "    local_file = unpack_url(\n",
      "  File \"C:\\Users\\User\\AppData\\Local\\Programs\\Python\\Python310\\lib\\site-packages\\pip\\_internal\\operations\\prepare.py\", line 239, in unpack_url\n",
      "    file = get_http_url(\n",
      "  File \"C:\\Users\\User\\AppData\\Local\\Programs\\Python\\Python310\\lib\\site-packages\\pip\\_internal\\operations\\prepare.py\", line 102, in get_http_url\n",
      "    from_path, content_type = download(link, temp_dir.path)\n",
      "  File \"C:\\Users\\User\\AppData\\Local\\Programs\\Python\\Python310\\lib\\site-packages\\pip\\_internal\\network\\download.py\", line 145, in __call__\n",
      "    for chunk in chunks:\n",
      "  File \"C:\\Users\\User\\AppData\\Local\\Programs\\Python\\Python310\\lib\\site-packages\\pip\\_internal\\cli\\progress_bars.py\", line 144, in iter\n",
      "    for x in it:\n",
      "  File \"C:\\Users\\User\\AppData\\Local\\Programs\\Python\\Python310\\lib\\site-packages\\pip\\_internal\\network\\utils.py\", line 63, in response_chunks\n",
      "    for chunk in response.raw.stream(\n",
      "  File \"C:\\Users\\User\\AppData\\Local\\Programs\\Python\\Python310\\lib\\site-packages\\pip\\_vendor\\urllib3\\response.py\", line 576, in stream\n",
      "    data = self.read(amt=amt, decode_content=decode_content)\n",
      "  File \"C:\\Users\\User\\AppData\\Local\\Programs\\Python\\Python310\\lib\\site-packages\\pip\\_vendor\\urllib3\\response.py\", line 512, in read\n",
      "    with self._error_catcher():\n",
      "  File \"C:\\Users\\User\\AppData\\Local\\Programs\\Python\\Python310\\lib\\contextlib.py\", line 153, in __exit__\n",
      "    self.gen.throw(typ, value, traceback)\n",
      "  File \"C:\\Users\\User\\AppData\\Local\\Programs\\Python\\Python310\\lib\\site-packages\\pip\\_vendor\\urllib3\\response.py\", line 443, in _error_catcher\n",
      "    raise ReadTimeoutError(self._pool, None, \"Read timed out.\")\n",
      "pip._vendor.urllib3.exceptions.ReadTimeoutError: HTTPSConnectionPool(host='files.pythonhosted.org', port=443): Read timed out.\n",
      "WARNING: You are using pip version 21.2.4; however, version 22.0.4 is available.\n",
      "You should consider upgrading via the 'C:\\Users\\User\\AppData\\Local\\Programs\\Python\\Python310\\python.exe -m pip install --upgrade pip' command.\n"
     ]
    },
    {
     "name": "stdout",
     "output_type": "stream",
     "text": [
      "Collecting pandas\n",
      "  Using cached pandas-1.4.2-cp310-cp310-win_amd64.whl (10.6 MB)\n",
      "Collecting pytz>=2020.1\n",
      "  Using cached pytz-2022.1-py2.py3-none-any.whl (503 kB)\n",
      "Requirement already satisfied: python-dateutil>=2.8.1 in c:\\users\\user\\appdata\\local\\programs\\python\\python310\\lib\\site-packages (from pandas) (2.8.2)\n",
      "Collecting numpy>=1.21.0\n",
      "  Downloading numpy-1.22.3-cp310-cp310-win_amd64.whl (14.7 MB)\n"
     ]
    }
   ],
   "source": [
    "pip install pandas"
   ]
  },
  {
   "cell_type": "code",
   "execution_count": 26,
   "metadata": {},
   "outputs": [
    {
     "ename": "ModuleNotFoundError",
     "evalue": "No module named 'pandas'",
     "output_type": "error",
     "traceback": [
      "\u001b[1;31m---------------------------------------------------------------------------\u001b[0m",
      "\u001b[1;31mModuleNotFoundError\u001b[0m                       Traceback (most recent call last)",
      "\u001b[1;32mc:\\Users\\User\\Desktop\\project\\git-test\\트위터_selenium.ipynb Cell 4'\u001b[0m in \u001b[0;36m<cell line: 8>\u001b[1;34m()\u001b[0m\n\u001b[0;32m      <a href='vscode-notebook-cell:/c%3A/Users/User/Desktop/project/git-test/%ED%8A%B8%EC%9C%84%ED%84%B0_selenium.ipynb#ch0000000?line=5'>6</a>\u001b[0m \u001b[39mimport\u001b[39;00m \u001b[39mdatetime\u001b[39;00m \u001b[39mas\u001b[39;00m \u001b[39mdt\u001b[39;00m\n\u001b[0;32m      <a href='vscode-notebook-cell:/c%3A/Users/User/Desktop/project/git-test/%ED%8A%B8%EC%9C%84%ED%84%B0_selenium.ipynb#ch0000000?line=6'>7</a>\u001b[0m \u001b[39mimport\u001b[39;00m \u001b[39mrequests\u001b[39;00m\n\u001b[1;32m----> <a href='vscode-notebook-cell:/c%3A/Users/User/Desktop/project/git-test/%ED%8A%B8%EC%9C%84%ED%84%B0_selenium.ipynb#ch0000000?line=7'>8</a>\u001b[0m \u001b[39mimport\u001b[39;00m \u001b[39mpandas\u001b[39;00m \u001b[39mas\u001b[39;00m \u001b[39mpd\u001b[39;00m\n\u001b[0;32m      <a href='vscode-notebook-cell:/c%3A/Users/User/Desktop/project/git-test/%ED%8A%B8%EC%9C%84%ED%84%B0_selenium.ipynb#ch0000000?line=8'>9</a>\u001b[0m \u001b[39mfrom\u001b[39;00m \u001b[39mbs4\u001b[39;00m \u001b[39mimport\u001b[39;00m BeautifulSoup\n\u001b[0;32m     <a href='vscode-notebook-cell:/c%3A/Users/User/Desktop/project/git-test/%ED%8A%B8%EC%9C%84%ED%84%B0_selenium.ipynb#ch0000000?line=9'>10</a>\u001b[0m \u001b[39m#from openpyxl import Workbook\u001b[39;00m\n",
      "\u001b[1;31mModuleNotFoundError\u001b[0m: No module named 'pandas'"
     ]
    }
   ],
   "source": [
    "from selenium import webdriver\n",
    "from selenium.webdriver import ActionChains\n",
    "from selenium.webdriver.common.keys import Keys\n",
    "from selenium.webdriver.common.by import By\n",
    "import time\n",
    "import datetime as dt\n",
    "import requests\n",
    "import pandas as pd\n",
    "from bs4 import BeautifulSoup\n",
    "#from openpyxl import Workbook\n",
    "\n",
    "driver = webdriver.Chrome()\n",
    "driver.maximize_window() # 브라우저 화면 최대화\n",
    "driver.get('https://twitter.com/search?q=%EB%AC%B4%EC%8B%A0%EC%82%AC&src=typed_query&f=live')\n",
    "time.sleep(1)\n",
    "SCROLL_PAUSE_SEC = 1\n",
    "\n",
    "# 스크롤 높이 가져옴\n",
    "last_height = driver.execute_script(\"return document.body.scrollHeight\")\n",
    "\n",
    "while True:\n",
    "    # 끝까지 스크롤 다운\n",
    "    driver.execute_script(\"window.scrollTo(0, document.body.scrollHeight);\")\n",
    "\n",
    "    # # 1초 대기\n",
    "    # time.sleep(SCROLL_PAUSE_SEC)\n",
    "\n",
    "    # 스크롤 다운 후 스크롤 높이 다시 가져옴\n",
    "    new_height = driver.execute_script(\"return document.body.scrollHeight\")\n",
    "    if new_height == last_height:\n",
    "        break\n",
    "    last_height = new_height"
   ]
  }
 ],
 "metadata": {
  "interpreter": {
   "hash": "aecd030d4c8316a52bf122072e28f84bcc79844c2684e041fef2e3f1d9f59078"
  },
  "kernelspec": {
   "display_name": "Python 3.10.1 64-bit",
   "language": "python",
   "name": "python3"
  },
  "language_info": {
   "codemirror_mode": {
    "name": "ipython",
    "version": 3
   },
   "file_extension": ".py",
   "mimetype": "text/x-python",
   "name": "python",
   "nbconvert_exporter": "python",
   "pygments_lexer": "ipython3",
   "version": "3.10.1"
  },
  "orig_nbformat": 4
 },
 "nbformat": 4,
 "nbformat_minor": 2
}
